[2025-01-28T06:22:04.509+0000] {local_task_job_runner.py:123} INFO - ::group::Pre task execution logs
[2025-01-28T06:22:04.519+0000] {taskinstance.py:2613} INFO - Dependencies all met for dep_context=non-requeueable deps ti=<TaskInstance: weather_dag.transform_load_weather_data manual__2025-01-28T06:17:47.556410+00:00 [queued]>
[2025-01-28T06:22:04.526+0000] {taskinstance.py:2613} INFO - Dependencies all met for dep_context=requeueable deps ti=<TaskInstance: weather_dag.transform_load_weather_data manual__2025-01-28T06:17:47.556410+00:00 [queued]>
[2025-01-28T06:22:04.526+0000] {taskinstance.py:2866} INFO - Starting attempt 3 of 3
[2025-01-28T06:22:04.549+0000] {taskinstance.py:2889} INFO - Executing <Task(PythonOperator): transform_load_weather_data> on 2025-01-28 06:17:47.556410+00:00
[2025-01-28T06:22:04.554+0000] {standard_task_runner.py:72} INFO - Started process 3862 to run task
[2025-01-28T06:22:04.560+0000] {standard_task_runner.py:104} INFO - Running: ['airflow', 'tasks', 'run', 'weather_dag', 'transform_load_weather_data', 'manual__2025-01-28T06:17:47.556410+00:00', '--job-id', '24', '--raw', '--subdir', '/home/ubuntu/airflow/dags/weather_dag.py', '--cfg-path', '/tmp/tmp9cxfqofn']
[2025-01-28T06:22:04.561+0000] {standard_task_runner.py:105} INFO - Job 24: Subtask transform_load_weather_data
[2025-01-28T06:22:04.598+0000] {task_command.py:467} INFO - Running <TaskInstance: weather_dag.transform_load_weather_data manual__2025-01-28T06:17:47.556410+00:00 [running]> on host ip-172-31-38-205.ap-southeast-2.compute.internal
[2025-01-28T06:22:04.788+0000] {taskinstance.py:3132} INFO - Exporting env vars: AIRFLOW_CTX_DAG_EMAIL='trinhminhquan2810@gmail.com' AIRFLOW_CTX_DAG_OWNER='airflow' AIRFLOW_CTX_DAG_ID='weather_dag' AIRFLOW_CTX_TASK_ID='transform_load_weather_data' AIRFLOW_CTX_EXECUTION_DATE='2025-01-28T06:17:47.556410+00:00' AIRFLOW_CTX_TRY_NUMBER='3' AIRFLOW_CTX_DAG_RUN_ID='manual__2025-01-28T06:17:47.556410+00:00'
[2025-01-28T06:22:04.789+0000] {logging_mixin.py:190} INFO - Task instance is in running state
[2025-01-28T06:22:04.789+0000] {logging_mixin.py:190} INFO -  Previous state of the Task instance: queued
[2025-01-28T06:22:04.790+0000] {logging_mixin.py:190} INFO - Current task name:transform_load_weather_data state:running start_date:2025-01-28 06:22:04.519338+00:00
[2025-01-28T06:22:04.790+0000] {logging_mixin.py:190} INFO - Dag name:weather_dag and current dag run status:running
[2025-01-28T06:22:04.790+0000] {taskinstance.py:731} INFO - ::endgroup::
[2025-01-28T06:22:04.828+0000] {taskinstance.py:3311} ERROR - Task failed with exception
Traceback (most recent call last):
  File "/home/ubuntu/.local/lib/python3.12/site-packages/fsspec/registry.py", line 246, in get_filesystem_class
    register_implementation(protocol, _import_class(bit["class"]))
                                      ^^^^^^^^^^^^^^^^^^^^^^^^^^^
  File "/home/ubuntu/.local/lib/python3.12/site-packages/fsspec/registry.py", line 281, in _import_class
    mod = importlib.import_module(mod)
          ^^^^^^^^^^^^^^^^^^^^^^^^^^^^
  File "/usr/lib/python3.12/importlib/__init__.py", line 90, in import_module
    return _bootstrap._gcd_import(name[level:], package, level)
           ^^^^^^^^^^^^^^^^^^^^^^^^^^^^^^^^^^^^^^^^^^^^^^^^^^^^
  File "<frozen importlib._bootstrap>", line 1387, in _gcd_import
  File "<frozen importlib._bootstrap>", line 1360, in _find_and_load
  File "<frozen importlib._bootstrap>", line 1324, in _find_and_load_unlocked
ModuleNotFoundError: No module named 's3fs'

The above exception was the direct cause of the following exception:

Traceback (most recent call last):
  File "/home/ubuntu/.local/lib/python3.12/site-packages/airflow/models/taskinstance.py", line 767, in _execute_task
    result = _execute_callable(context=context, **execute_callable_kwargs)
             ^^^^^^^^^^^^^^^^^^^^^^^^^^^^^^^^^^^^^^^^^^^^^^^^^^^^^^^^^^^^^
  File "/home/ubuntu/.local/lib/python3.12/site-packages/airflow/models/taskinstance.py", line 733, in _execute_callable
    return ExecutionCallableRunner(
           ^^^^^^^^^^^^^^^^^^^^^^^^
  File "/home/ubuntu/.local/lib/python3.12/site-packages/airflow/utils/operator_helpers.py", line 252, in run
    return self.func(*args, **kwargs)
           ^^^^^^^^^^^^^^^^^^^^^^^^^^
  File "/home/ubuntu/.local/lib/python3.12/site-packages/airflow/models/baseoperator.py", line 422, in wrapper
    return func(self, *args, **kwargs)
           ^^^^^^^^^^^^^^^^^^^^^^^^^^^
  File "/home/ubuntu/.local/lib/python3.12/site-packages/airflow/operators/python.py", line 238, in execute
    return_value = self.execute_callable()
                   ^^^^^^^^^^^^^^^^^^^^^^^
  File "/home/ubuntu/.local/lib/python3.12/site-packages/airflow/operators/python.py", line 256, in execute_callable
    return runner.run(*self.op_args, **self.op_kwargs)
           ^^^^^^^^^^^^^^^^^^^^^^^^^^^^^^^^^^^^^^^^^^^
  File "/home/ubuntu/.local/lib/python3.12/site-packages/airflow/utils/operator_helpers.py", line 252, in run
    return self.func(*args, **kwargs)
           ^^^^^^^^^^^^^^^^^^^^^^^^^^
  File "/home/ubuntu/airflow/dags/weather_dag.py", line 53, in transform_load_data
    df_data.to_csv(f"s3://weatherapiairflowyoutubebucket-yml/{dt_string}.csv", index=False, storage_options=aws_credentials)
  File "/home/ubuntu/.local/lib/python3.12/site-packages/pandas/util/_decorators.py", line 333, in wrapper
    return func(*args, **kwargs)
           ^^^^^^^^^^^^^^^^^^^^^
  File "/home/ubuntu/.local/lib/python3.12/site-packages/pandas/core/generic.py", line 3967, in to_csv
    return DataFrameRenderer(formatter).to_csv(
           ^^^^^^^^^^^^^^^^^^^^^^^^^^^^^^^^^^^^
  File "/home/ubuntu/.local/lib/python3.12/site-packages/pandas/io/formats/format.py", line 1014, in to_csv
    csv_formatter.save()
  File "/home/ubuntu/.local/lib/python3.12/site-packages/pandas/io/formats/csvs.py", line 251, in save
    with get_handle(
         ^^^^^^^^^^^
  File "/home/ubuntu/.local/lib/python3.12/site-packages/pandas/io/common.py", line 728, in get_handle
    ioargs = _get_filepath_or_buffer(
             ^^^^^^^^^^^^^^^^^^^^^^^^
  File "/home/ubuntu/.local/lib/python3.12/site-packages/pandas/io/common.py", line 430, in _get_filepath_or_buffer
    file_obj = fsspec.open(
               ^^^^^^^^^^^^
  File "/home/ubuntu/.local/lib/python3.12/site-packages/fsspec/core.py", line 491, in open
    out = open_files(
          ^^^^^^^^^^^
  File "/home/ubuntu/.local/lib/python3.12/site-packages/fsspec/core.py", line 295, in open_files
    fs, fs_token, paths = get_fs_token_paths(
                          ^^^^^^^^^^^^^^^^^^^
  File "/home/ubuntu/.local/lib/python3.12/site-packages/fsspec/core.py", line 655, in get_fs_token_paths
    chain = _un_chain(urlpath0, storage_options or {})
            ^^^^^^^^^^^^^^^^^^^^^^^^^^^^^^^^^^^^^^^^^^
  File "/home/ubuntu/.local/lib/python3.12/site-packages/fsspec/core.py", line 351, in _un_chain
    cls = get_filesystem_class(protocol)
          ^^^^^^^^^^^^^^^^^^^^^^^^^^^^^^
  File "/home/ubuntu/.local/lib/python3.12/site-packages/fsspec/registry.py", line 248, in get_filesystem_class
    raise ImportError(bit["err"]) from e
ImportError: Install s3fs to access S3
[2025-01-28T06:22:04.855+0000] {logging_mixin.py:190} INFO - Task instance in failure state
[2025-01-28T06:22:04.856+0000] {logging_mixin.py:190} INFO - Task start:2025-01-28 06:22:04.519338+00:00 end:2025-01-28 06:22:04.855671+00:00 duration:0.336333
[2025-01-28T06:22:04.857+0000] {logging_mixin.py:190} INFO - Task:<Task(PythonOperator): transform_load_weather_data> dag:<DAG: weather_dag> dagrun:<DagRun weather_dag @ 2025-01-28 06:17:47.556410+00:00: manual__2025-01-28T06:17:47.556410+00:00, state:running, queued_at: 2025-01-28 06:17:47.564276+00:00. externally triggered: True>
[2025-01-28T06:22:04.857+0000] {logging_mixin.py:190} INFO - Failure caused by Install s3fs to access S3
[2025-01-28T06:22:04.857+0000] {taskinstance.py:1225} INFO - Marking task as FAILED. dag_id=weather_dag, task_id=transform_load_weather_data, run_id=manual__2025-01-28T06:17:47.556410+00:00, execution_date=20250128T061747, start_date=20250128T062204, end_date=20250128T062204
[2025-01-28T06:22:04.870+0000] {logging_mixin.py:190} WARNING - /home/ubuntu/.local/lib/python3.12/site-packages/airflow/utils/email.py:155 RemovedInAirflow3Warning: Fetching SMTP credentials from configuration variables will be deprecated in a future release. Please set credentials using a connection instead.
[2025-01-28T06:22:04.871+0000] {configuration.py:1074} WARNING - section/key [smtp/smtp_user] not found in config
[2025-01-28T06:22:04.871+0000] {email.py:272} INFO - Email alerting: attempt 1
[2025-01-28T06:22:04.874+0000] {configuration.py:1074} WARNING - section/key [smtp/smtp_user] not found in config
[2025-01-28T06:22:04.875+0000] {email.py:272} INFO - Email alerting: attempt 1
[2025-01-28T06:22:04.875+0000] {taskinstance.py:1234} ERROR - Failed to send email to: ['trinhminhquan2810@gmail.com']
Traceback (most recent call last):
  File "/home/ubuntu/.local/lib/python3.12/site-packages/fsspec/registry.py", line 246, in get_filesystem_class
    register_implementation(protocol, _import_class(bit["class"]))
                                      ^^^^^^^^^^^^^^^^^^^^^^^^^^^
  File "/home/ubuntu/.local/lib/python3.12/site-packages/fsspec/registry.py", line 281, in _import_class
    mod = importlib.import_module(mod)
          ^^^^^^^^^^^^^^^^^^^^^^^^^^^^
  File "/usr/lib/python3.12/importlib/__init__.py", line 90, in import_module
    return _bootstrap._gcd_import(name[level:], package, level)
           ^^^^^^^^^^^^^^^^^^^^^^^^^^^^^^^^^^^^^^^^^^^^^^^^^^^^
  File "<frozen importlib._bootstrap>", line 1387, in _gcd_import
  File "<frozen importlib._bootstrap>", line 1360, in _find_and_load
  File "<frozen importlib._bootstrap>", line 1324, in _find_and_load_unlocked
ModuleNotFoundError: No module named 's3fs'

The above exception was the direct cause of the following exception:

Traceback (most recent call last):
  File "/home/ubuntu/.local/lib/python3.12/site-packages/airflow/models/taskinstance.py", line 273, in _run_raw_task
    TaskInstance._execute_task_with_callbacks(
  File "/home/ubuntu/.local/lib/python3.12/site-packages/airflow/models/taskinstance.py", line 3159, in _execute_task_with_callbacks
    result = self._execute_task(context, task_orig)
             ^^^^^^^^^^^^^^^^^^^^^^^^^^^^^^^^^^^^^^
  File "/home/ubuntu/.local/lib/python3.12/site-packages/airflow/models/taskinstance.py", line 3183, in _execute_task
    return _execute_task(self, context, task_orig)
           ^^^^^^^^^^^^^^^^^^^^^^^^^^^^^^^^^^^^^^^
  File "/home/ubuntu/.local/lib/python3.12/site-packages/airflow/models/taskinstance.py", line 767, in _execute_task
    result = _execute_callable(context=context, **execute_callable_kwargs)
             ^^^^^^^^^^^^^^^^^^^^^^^^^^^^^^^^^^^^^^^^^^^^^^^^^^^^^^^^^^^^^
  File "/home/ubuntu/.local/lib/python3.12/site-packages/airflow/models/taskinstance.py", line 733, in _execute_callable
    return ExecutionCallableRunner(
           ^^^^^^^^^^^^^^^^^^^^^^^^
  File "/home/ubuntu/.local/lib/python3.12/site-packages/airflow/utils/operator_helpers.py", line 252, in run
    return self.func(*args, **kwargs)
           ^^^^^^^^^^^^^^^^^^^^^^^^^^
  File "/home/ubuntu/.local/lib/python3.12/site-packages/airflow/models/baseoperator.py", line 422, in wrapper
    return func(self, *args, **kwargs)
           ^^^^^^^^^^^^^^^^^^^^^^^^^^^
  File "/home/ubuntu/.local/lib/python3.12/site-packages/airflow/operators/python.py", line 238, in execute
    return_value = self.execute_callable()
                   ^^^^^^^^^^^^^^^^^^^^^^^
  File "/home/ubuntu/.local/lib/python3.12/site-packages/airflow/operators/python.py", line 256, in execute_callable
    return runner.run(*self.op_args, **self.op_kwargs)
           ^^^^^^^^^^^^^^^^^^^^^^^^^^^^^^^^^^^^^^^^^^^
  File "/home/ubuntu/.local/lib/python3.12/site-packages/airflow/utils/operator_helpers.py", line 252, in run
    return self.func(*args, **kwargs)
           ^^^^^^^^^^^^^^^^^^^^^^^^^^
  File "/home/ubuntu/airflow/dags/weather_dag.py", line 53, in transform_load_data
    df_data.to_csv(f"s3://weatherapiairflowyoutubebucket-yml/{dt_string}.csv", index=False, storage_options=aws_credentials)
  File "/home/ubuntu/.local/lib/python3.12/site-packages/pandas/util/_decorators.py", line 333, in wrapper
    return func(*args, **kwargs)
           ^^^^^^^^^^^^^^^^^^^^^
  File "/home/ubuntu/.local/lib/python3.12/site-packages/pandas/core/generic.py", line 3967, in to_csv
    return DataFrameRenderer(formatter).to_csv(
           ^^^^^^^^^^^^^^^^^^^^^^^^^^^^^^^^^^^^
  File "/home/ubuntu/.local/lib/python3.12/site-packages/pandas/io/formats/format.py", line 1014, in to_csv
    csv_formatter.save()
  File "/home/ubuntu/.local/lib/python3.12/site-packages/pandas/io/formats/csvs.py", line 251, in save
    with get_handle(
         ^^^^^^^^^^^
  File "/home/ubuntu/.local/lib/python3.12/site-packages/pandas/io/common.py", line 728, in get_handle
    ioargs = _get_filepath_or_buffer(
             ^^^^^^^^^^^^^^^^^^^^^^^^
  File "/home/ubuntu/.local/lib/python3.12/site-packages/pandas/io/common.py", line 430, in _get_filepath_or_buffer
    file_obj = fsspec.open(
               ^^^^^^^^^^^^
  File "/home/ubuntu/.local/lib/python3.12/site-packages/fsspec/core.py", line 491, in open
    out = open_files(
          ^^^^^^^^^^^
  File "/home/ubuntu/.local/lib/python3.12/site-packages/fsspec/core.py", line 295, in open_files
    fs, fs_token, paths = get_fs_token_paths(
                          ^^^^^^^^^^^^^^^^^^^
  File "/home/ubuntu/.local/lib/python3.12/site-packages/fsspec/core.py", line 655, in get_fs_token_paths
    chain = _un_chain(urlpath0, storage_options or {})
            ^^^^^^^^^^^^^^^^^^^^^^^^^^^^^^^^^^^^^^^^^^
  File "/home/ubuntu/.local/lib/python3.12/site-packages/fsspec/core.py", line 351, in _un_chain
    cls = get_filesystem_class(protocol)
          ^^^^^^^^^^^^^^^^^^^^^^^^^^^^^^
  File "/home/ubuntu/.local/lib/python3.12/site-packages/fsspec/registry.py", line 248, in get_filesystem_class
    raise ImportError(bit["err"]) from e
ImportError: Install s3fs to access S3

During handling of the above exception, another exception occurred:

Traceback (most recent call last):
  File "/home/ubuntu/.local/lib/python3.12/site-packages/airflow/models/taskinstance.py", line 1442, in _email_alert
    send_email(task.email, subject, html_content)
  File "/home/ubuntu/.local/lib/python3.12/site-packages/airflow/utils/email.py", line 80, in send_email
    return backend(
           ^^^^^^^^
  File "/home/ubuntu/.local/lib/python3.12/site-packages/airflow/utils/email.py", line 155, in send_email_smtp
    send_mime_email(e_from=mail_from, e_to=recipients, mime_msg=msg, conn_id=conn_id, dryrun=dryrun)
  File "/home/ubuntu/.local/lib/python3.12/site-packages/airflow/utils/email.py", line 274, in send_mime_email
    smtp_conn = _get_smtp_connection(smtp_host, smtp_port, smtp_timeout, smtp_ssl)
                ^^^^^^^^^^^^^^^^^^^^^^^^^^^^^^^^^^^^^^^^^^^^^^^^^^^^^^^^^^^^^^^^^^
  File "/home/ubuntu/.local/lib/python3.12/site-packages/airflow/utils/email.py", line 318, in _get_smtp_connection
    return smtplib.SMTP(host=host, port=port, timeout=timeout)
           ^^^^^^^^^^^^^^^^^^^^^^^^^^^^^^^^^^^^^^^^^^^^^^^^^^^
  File "/usr/lib/python3.12/smtplib.py", line 255, in __init__
    (code, msg) = self.connect(host, port)
                  ^^^^^^^^^^^^^^^^^^^^^^^^
  File "/usr/lib/python3.12/smtplib.py", line 341, in connect
    self.sock = self._get_socket(host, port, self.timeout)
                ^^^^^^^^^^^^^^^^^^^^^^^^^^^^^^^^^^^^^^^^^^
  File "/usr/lib/python3.12/smtplib.py", line 312, in _get_socket
    return socket.create_connection((host, port), timeout,
           ^^^^^^^^^^^^^^^^^^^^^^^^^^^^^^^^^^^^^^^^^^^^^^^
  File "/usr/lib/python3.12/socket.py", line 852, in create_connection
    raise exceptions[0]
  File "/usr/lib/python3.12/socket.py", line 837, in create_connection
    sock.connect(sa)
ConnectionRefusedError: [Errno 111] Connection refused

During handling of the above exception, another exception occurred:

Traceback (most recent call last):
  File "/home/ubuntu/.local/lib/python3.12/site-packages/airflow/models/taskinstance.py", line 1232, in _handle_failure
    task_instance.email_alert(error, failure_context["task"])
  File "/home/ubuntu/.local/lib/python3.12/site-packages/airflow/models/taskinstance.py", line 3605, in email_alert
    _email_alert(task_instance=self, exception=exception, task=task)
  File "/home/ubuntu/.local/lib/python3.12/site-packages/airflow/models/taskinstance.py", line 1444, in _email_alert
    send_email(task.email, subject, html_content_err)
  File "/home/ubuntu/.local/lib/python3.12/site-packages/airflow/utils/email.py", line 80, in send_email
    return backend(
           ^^^^^^^^
  File "/home/ubuntu/.local/lib/python3.12/site-packages/airflow/utils/email.py", line 155, in send_email_smtp
    send_mime_email(e_from=mail_from, e_to=recipients, mime_msg=msg, conn_id=conn_id, dryrun=dryrun)
  File "/home/ubuntu/.local/lib/python3.12/site-packages/airflow/utils/email.py", line 274, in send_mime_email
    smtp_conn = _get_smtp_connection(smtp_host, smtp_port, smtp_timeout, smtp_ssl)
                ^^^^^^^^^^^^^^^^^^^^^^^^^^^^^^^^^^^^^^^^^^^^^^^^^^^^^^^^^^^^^^^^^^
  File "/home/ubuntu/.local/lib/python3.12/site-packages/airflow/utils/email.py", line 318, in _get_smtp_connection
    return smtplib.SMTP(host=host, port=port, timeout=timeout)
           ^^^^^^^^^^^^^^^^^^^^^^^^^^^^^^^^^^^^^^^^^^^^^^^^^^^
  File "/usr/lib/python3.12/smtplib.py", line 255, in __init__
    (code, msg) = self.connect(host, port)
                  ^^^^^^^^^^^^^^^^^^^^^^^^
  File "/usr/lib/python3.12/smtplib.py", line 341, in connect
    self.sock = self._get_socket(host, port, self.timeout)
                ^^^^^^^^^^^^^^^^^^^^^^^^^^^^^^^^^^^^^^^^^^
  File "/usr/lib/python3.12/smtplib.py", line 312, in _get_socket
    return socket.create_connection((host, port), timeout,
           ^^^^^^^^^^^^^^^^^^^^^^^^^^^^^^^^^^^^^^^^^^^^^^^
  File "/usr/lib/python3.12/socket.py", line 852, in create_connection
    raise exceptions[0]
  File "/usr/lib/python3.12/socket.py", line 837, in create_connection
    sock.connect(sa)
ConnectionRefusedError: [Errno 111] Connection refused
[2025-01-28T06:22:04.896+0000] {taskinstance.py:340} INFO - ::group::Post task execution logs
[2025-01-28T06:22:04.896+0000] {standard_task_runner.py:124} ERROR - Failed to execute job 24 for task transform_load_weather_data (Install s3fs to access S3; 3862)
Traceback (most recent call last):
  File "/home/ubuntu/.local/lib/python3.12/site-packages/fsspec/registry.py", line 246, in get_filesystem_class
    register_implementation(protocol, _import_class(bit["class"]))
                                      ^^^^^^^^^^^^^^^^^^^^^^^^^^^
  File "/home/ubuntu/.local/lib/python3.12/site-packages/fsspec/registry.py", line 281, in _import_class
    mod = importlib.import_module(mod)
          ^^^^^^^^^^^^^^^^^^^^^^^^^^^^
  File "/usr/lib/python3.12/importlib/__init__.py", line 90, in import_module
    return _bootstrap._gcd_import(name[level:], package, level)
           ^^^^^^^^^^^^^^^^^^^^^^^^^^^^^^^^^^^^^^^^^^^^^^^^^^^^
  File "<frozen importlib._bootstrap>", line 1387, in _gcd_import
  File "<frozen importlib._bootstrap>", line 1360, in _find_and_load
  File "<frozen importlib._bootstrap>", line 1324, in _find_and_load_unlocked
ModuleNotFoundError: No module named 's3fs'

The above exception was the direct cause of the following exception:

Traceback (most recent call last):
  File "/home/ubuntu/.local/lib/python3.12/site-packages/airflow/task/task_runner/standard_task_runner.py", line 117, in _start_by_fork
    ret = args.func(args, dag=self.dag)
          ^^^^^^^^^^^^^^^^^^^^^^^^^^^^^
  File "/home/ubuntu/.local/lib/python3.12/site-packages/airflow/cli/cli_config.py", line 49, in command
    return func(*args, **kwargs)
           ^^^^^^^^^^^^^^^^^^^^^
  File "/home/ubuntu/.local/lib/python3.12/site-packages/airflow/utils/cli.py", line 116, in wrapper
    return f(*args, **kwargs)
           ^^^^^^^^^^^^^^^^^^
  File "/home/ubuntu/.local/lib/python3.12/site-packages/airflow/cli/commands/task_command.py", line 483, in task_run
    task_return_code = _run_task_by_selected_method(args, _dag, ti)
                       ^^^^^^^^^^^^^^^^^^^^^^^^^^^^^^^^^^^^^^^^^^^^
  File "/home/ubuntu/.local/lib/python3.12/site-packages/airflow/cli/commands/task_command.py", line 256, in _run_task_by_selected_method
    return _run_raw_task(args, ti)
           ^^^^^^^^^^^^^^^^^^^^^^^
  File "/home/ubuntu/.local/lib/python3.12/site-packages/airflow/cli/commands/task_command.py", line 341, in _run_raw_task
    return ti._run_raw_task(
           ^^^^^^^^^^^^^^^^^
  File "/home/ubuntu/.local/lib/python3.12/site-packages/airflow/utils/session.py", line 97, in wrapper
    return func(*args, session=session, **kwargs)
           ^^^^^^^^^^^^^^^^^^^^^^^^^^^^^^^^^^^^^^
  File "/home/ubuntu/.local/lib/python3.12/site-packages/airflow/models/taskinstance.py", line 3005, in _run_raw_task
    return _run_raw_task(
           ^^^^^^^^^^^^^^
  File "/home/ubuntu/.local/lib/python3.12/site-packages/airflow/models/taskinstance.py", line 273, in _run_raw_task
    TaskInstance._execute_task_with_callbacks(
  File "/home/ubuntu/.local/lib/python3.12/site-packages/airflow/models/taskinstance.py", line 3159, in _execute_task_with_callbacks
    result = self._execute_task(context, task_orig)
             ^^^^^^^^^^^^^^^^^^^^^^^^^^^^^^^^^^^^^^
  File "/home/ubuntu/.local/lib/python3.12/site-packages/airflow/models/taskinstance.py", line 3183, in _execute_task
    return _execute_task(self, context, task_orig)
           ^^^^^^^^^^^^^^^^^^^^^^^^^^^^^^^^^^^^^^^
  File "/home/ubuntu/.local/lib/python3.12/site-packages/airflow/models/taskinstance.py", line 767, in _execute_task
    result = _execute_callable(context=context, **execute_callable_kwargs)
             ^^^^^^^^^^^^^^^^^^^^^^^^^^^^^^^^^^^^^^^^^^^^^^^^^^^^^^^^^^^^^
  File "/home/ubuntu/.local/lib/python3.12/site-packages/airflow/models/taskinstance.py", line 733, in _execute_callable
    return ExecutionCallableRunner(
           ^^^^^^^^^^^^^^^^^^^^^^^^
  File "/home/ubuntu/.local/lib/python3.12/site-packages/airflow/utils/operator_helpers.py", line 252, in run
    return self.func(*args, **kwargs)
           ^^^^^^^^^^^^^^^^^^^^^^^^^^
  File "/home/ubuntu/.local/lib/python3.12/site-packages/airflow/models/baseoperator.py", line 422, in wrapper
    return func(self, *args, **kwargs)
           ^^^^^^^^^^^^^^^^^^^^^^^^^^^
  File "/home/ubuntu/.local/lib/python3.12/site-packages/airflow/operators/python.py", line 238, in execute
    return_value = self.execute_callable()
                   ^^^^^^^^^^^^^^^^^^^^^^^
  File "/home/ubuntu/.local/lib/python3.12/site-packages/airflow/operators/python.py", line 256, in execute_callable
    return runner.run(*self.op_args, **self.op_kwargs)
           ^^^^^^^^^^^^^^^^^^^^^^^^^^^^^^^^^^^^^^^^^^^
  File "/home/ubuntu/.local/lib/python3.12/site-packages/airflow/utils/operator_helpers.py", line 252, in run
    return self.func(*args, **kwargs)
           ^^^^^^^^^^^^^^^^^^^^^^^^^^
  File "/home/ubuntu/airflow/dags/weather_dag.py", line 53, in transform_load_data
    df_data.to_csv(f"s3://weatherapiairflowyoutubebucket-yml/{dt_string}.csv", index=False, storage_options=aws_credentials)
  File "/home/ubuntu/.local/lib/python3.12/site-packages/pandas/util/_decorators.py", line 333, in wrapper
    return func(*args, **kwargs)
           ^^^^^^^^^^^^^^^^^^^^^
  File "/home/ubuntu/.local/lib/python3.12/site-packages/pandas/core/generic.py", line 3967, in to_csv
    return DataFrameRenderer(formatter).to_csv(
           ^^^^^^^^^^^^^^^^^^^^^^^^^^^^^^^^^^^^
  File "/home/ubuntu/.local/lib/python3.12/site-packages/pandas/io/formats/format.py", line 1014, in to_csv
    csv_formatter.save()
  File "/home/ubuntu/.local/lib/python3.12/site-packages/pandas/io/formats/csvs.py", line 251, in save
    with get_handle(
         ^^^^^^^^^^^
  File "/home/ubuntu/.local/lib/python3.12/site-packages/pandas/io/common.py", line 728, in get_handle
    ioargs = _get_filepath_or_buffer(
             ^^^^^^^^^^^^^^^^^^^^^^^^
  File "/home/ubuntu/.local/lib/python3.12/site-packages/pandas/io/common.py", line 430, in _get_filepath_or_buffer
    file_obj = fsspec.open(
               ^^^^^^^^^^^^
  File "/home/ubuntu/.local/lib/python3.12/site-packages/fsspec/core.py", line 491, in open
    out = open_files(
          ^^^^^^^^^^^
  File "/home/ubuntu/.local/lib/python3.12/site-packages/fsspec/core.py", line 295, in open_files
    fs, fs_token, paths = get_fs_token_paths(
                          ^^^^^^^^^^^^^^^^^^^
  File "/home/ubuntu/.local/lib/python3.12/site-packages/fsspec/core.py", line 655, in get_fs_token_paths
    chain = _un_chain(urlpath0, storage_options or {})
            ^^^^^^^^^^^^^^^^^^^^^^^^^^^^^^^^^^^^^^^^^^
  File "/home/ubuntu/.local/lib/python3.12/site-packages/fsspec/core.py", line 351, in _un_chain
    cls = get_filesystem_class(protocol)
          ^^^^^^^^^^^^^^^^^^^^^^^^^^^^^^
  File "/home/ubuntu/.local/lib/python3.12/site-packages/fsspec/registry.py", line 248, in get_filesystem_class
    raise ImportError(bit["err"]) from e
ImportError: Install s3fs to access S3
[2025-01-28T06:22:04.935+0000] {local_task_job_runner.py:266} INFO - Task exited with return code 1
[2025-01-28T06:22:04.945+0000] {taskinstance.py:3895} INFO - 0 downstream tasks scheduled from follow-on schedule check
[2025-01-28T06:22:04.947+0000] {local_task_job_runner.py:245} INFO - ::endgroup::
